Workbook
Name Categoria: 'Strutture ricettive'!$A$2:$A$1048576
Name Città: 'Strutture ricettive'!$E$2:$E$1048576
Name Denominazione: 'Strutture ricettive'!$B$2:$B$1048576
Name Indirizzo: 'Strutture ricettive'!$C$2:$C$1048576
Name Indirizzo_di_posta_elettronica: 'Strutture ricettive'!$K$2:$K$1048576
Name Indirizzo_internet: 'Strutture ricettive'!$H$2:$H$1048576
Name Localita: 'Strutture ricettive'!$F$2:$F$1048576
Name Nome_Struttura: '[1]Strutture ricettive'!$B$2:$B$1048576

Sheet Strutture ricettive
A1: Categoria | B1: Strutture | C1: Indirizzo | D1: Indirizzo | E1: Città | F1: Localita | G1: Località | I1: Colonna Appoggio Indirizzo Internet | L1: Colonna Appoggio Posta elettronica | M1: EMAIL | N1: Indirizzo internet | O1: Indirizzo di posta elettronica | Q1: CATEGORIA | S1: ELENCO STRUTTURE
A2: TURISMO RURALE | B2: COUNTRY HOUSE LOCALITA' GIROFALCO | C2: Via Girfalco, 26 | D2: =PROPER(C2) -> Via Girfalco, 26 | E2: URBINO | F2: N/a | G2: =PROPER(F2) -> N/A | H2: www.girfalco.it | I2: =IF(ISERROR(FIND("@",H2)),"SITO","EMAIL") -> SITO | J2: =IF(I2="SITO",H2," ") -> www.girfalco.it | K2: info@girfalco.it | L2: =IF(ISERROR(FIND("@",K2)),"SITO","EMAIL") -> EMAIL | M2: =IF(L2="EMAIL",K2, " ") -> info@girfalco.it | N2: =IF(J2<>" ", J2, "N/a") -> www.girfalco.it | O2: =IF(M2 <> " ", M2,"N/a") -> info@girfalco.it | Q2: {=_xlfn.UNIQUE(A2:A6259)} -> TURISMO RURALE | S2: COUNTRY HOUSE LOCALITA' GIROFALCO
A3: ALTRI ALLOGGI PRIVATI | B3: STAGNOZZI STEFANIA | C3: Via Candigliano 5 | D3: =PROPER(C3) -> Via Candigliano 5 | E3: ACQUALAGNA | F3: ACQUALAGNA | G3: =PROPER(F3) -> Acqualagna | H3: N/a | I3: =IF(ISERROR(FIND("@",H3)),"SITO","EMAIL") -> SITO | J3: =IF(I3="SITO",H3," ") -> N/a | K3: gigliovitto@libero.it | L3: =IF(ISERROR(FIND("@",K3)),"SITO","EMAIL") -> EMAIL | M3: =IF(L3="EMAIL",K3, " ") -> gigliovitto@libero.it | N3: =IF(J3<>" ", J3, "N/a") -> N/a | O3: =IF(M3 <> " ", M3,"N/a") -> gigliovitto@libero.it | Q3: ALTRI ALLOGGI PRIVATI | S3: STAGNOZZI STEFANIA
A4: ALTRI ALLOGGI PRIVATI | B4: GORGOLINI ALESSANDRO | C4: Via San Gregorio 9 | D4: =PROPER(C4) -> Via San Gregorio 9 | E4: ACQUALAGNA | F4: ACQUALAGNA | G4: =PROPER(F4) -> Acqualagna | H4: N/a | I4: =IF(ISERROR(FIND("@",H4)),"SITO","EMAIL") -> SITO | J4: =IF(I4="SITO",H4," ") -> N/a | K4: ale.gorgolini@gmail.com | L4: =IF(ISERROR(FIND("@",K4)),"SITO","EMAIL") -> EMAIL | M4: =IF(L4="EMAIL",K4, " ") -> ale.gorgolini@gmail.com | N4: =IF(J4<>" ", J4, "N/a") -> N/a | O4: =IF(M4 <> " ", M4,"N/a") -> ale.gorgolini@gmail.com | Q4: ALBERGHI | S4: GORGOLINI ALESSANDRO
A5: ALBERGHI | B5: LEON D'ORO | C5: Via Flaminia 213 | D5: =PROPER(C5) -> Via Flaminia 213 | E5: ACQUALAGNA | F5: ACQUALAGNA | G5: =PROPER(F5) -> Acqualagna | H5: N/a | I5: =IF(ISERROR(FIND("@",H5)),"SITO","EMAIL") -> SITO | J5: =IF(I5="SITO",H5," ") -> N/a | K5: N/a | L5: =IF(ISERROR(FIND("@",K5)),"SITO","EMAIL") -> SITO | M5: =IF(L5="EMAIL",K5, " ") | N5: =IF(J5<>" ", J5, "N/a") -> N/a | O5: =IF(M5 <> " ", M5,"N/a") -> N/a | Q5: BED & BREAKFAST | S5: LEON D'ORO
A6: ALBERGHI | B6: ALBERGO DOMUS MARIAE | C6: viale Ezio Scaglioni 17 | D6: =PROPER(C6) -> Viale Ezio Scaglioni 17 | E6: ACQUALAGNA | F6: ACQUALAGNA | G6: =PROPER(F6) -> Acqualagna | H6: N/a | I6: =IF(ISERROR(FIND("@",H6)),"SITO","EMAIL") -> SITO | J6: =IF(I6="SITO",H6," ") -> N/a | K6: giulianaspini@gmail.com | L6: =IF(ISERROR(FIND("@",K6)),"SITO","EMAIL") -> EMAIL | M6: =IF(L6="EMAIL",K6, " ") -> giulianaspini@gmail.com | N6: =IF(J6<>" ", J6, "N/a") -> N/a | O6: =IF(M6 <> " ", M6,"N/a") -> giulianaspini@gmail.com | Q6: ALLOGGI AGRITURISTICI | S6: ALBERGO DOMUS MARIAE
A7: ALTRI ALLOGGI PRIVATI | B7: TORRE COLOMBARA DI FRONTINO | C7: STRADA FRONTINO 24/B | D7: =PROPER(C7) -> Strada Frontino 24/B | E7: ACQUALAGNA | F7: ACQUALAGNA | G7: =PROPER(F7) -> Acqualagna | H7: N/a | I7: =IF(ISERROR(FIND("@",H7)),"SITO","EMAIL") -> SITO | J7: =IF(I7="SITO",H7," ") -> N/a | K7: luccardi.sandro@gmail.com | L7: =IF(ISERROR(FIND("@",K7)),"SITO","EMAIL") -> EMAIL | M7: =IF(L7="EMAIL",K7, " ") -> luccardi.sandro@gmail.com | N7: =IF(J7<>" ", J7, "N/a") -> N/a | O7: =IF(M7 <> " ", M7,"N/a") -> luccardi.sandro@gmail.com | Q7: ALLOGGI IN AFFITTO | S7: TORRE COLOMBARA DI FRONTINO
A8: BED & BREAKFAST | B8: B&B AQUILEGIA | C8: via Furlo 12 | D8: =PROPER(C8) -> Via Furlo 12 | E8: ACQUALAGNA | F8: Furlo | G8: =PROPER(F8) -> Furlo | H8: www.aquilegiabeb.com | I8: =IF(ISERROR(FIND("@",H8)),"SITO","EMAIL") -> SITO | J8: =IF(I8="SITO",H8," ") -> www.aquilegiabeb.com | K8: info@aquilegiabeb.com | L8: =IF(ISERROR(FIND("@",K8)),"SITO","EMAIL") -> EMAIL | M8: =IF(L8="EMAIL",K8, " ") -> info@aquilegiabeb.com | N8: =IF(J8<>" ", J8, "N/a") -> www.aquilegiabeb.com | O8: =IF(M8 <> " ", M8,"N/a") -> info@aquilegiabeb.com | Q8: AREE DI SOSTA (PLEIN AIR) | S8: B&B AQUILEGIA
A9: ALLOGGI AGRITURISTICI | B9: DEL FRONTINO | C9: strada frontino 23 | D9: =PROPER(C9) -> Strada Frontino 23 | E9: ACQUALAGNA | F9: ACQUALAGNA | G9: =PROPER(F9) -> Acqualagna | H9: N/a | I9: =IF(ISERROR(FIND("@",H9)),"SITO","EMAIL") -> SITO | J9: =IF(I9="SITO",H9," ") -> N/a | K9: N/a | L9: =IF(ISERROR(FIND("@",K9)),"SITO","EMAIL") -> SITO | M9: =IF(L9="EMAIL",K9, " ") | N9: =IF(J9<>" ", J9, "N/a") -> N/a | O9: =IF(M9 <> " ", M9,"N/a") -> N/a | Q9: OSTELLI PER LA GIOVENTU' | S9: DEL FRONTINO
A10: ALBERGHI | B10: LA GINESTRA | C10: via Furlo 17 | D10: =PROPER(C10) -> Via Furlo 17 | E10: ACQUALAGNA | F10: ACQUALAGNA | G10: =PROPER(F10) -> Acqualagna | H10: www.ginestrafurlo.it | I10: =IF(ISERROR(FIND("@",H10)),"SITO","EMAIL") -> SITO | J10: =IF(I10="SITO",H10," ") -> www.ginestrafurlo.it | K10: info@ginestrafurlo.it | L10: =IF(ISERROR(FIND("@",K10)),"SITO","EMAIL") -> EMAIL | M10: =IF(L10="EMAIL",K10, " ") -> info@ginestrafurlo.it | N10: =IF(J10<>" ", J10, "N/a") -> www.ginestrafurlo.it | O10: =IF(M10 <> " ", M10,"N/a") -> info@ginestrafurlo.it | Q10: CASE PER FERIE | S10: LA GINESTRA
A11: ALBERGHI | B11: BIRRA AL POZZO | C11: via Pianacce 12 | D11: =PROPER(C11) -> Via Pianacce 12 | E11: ACQUALAGNA | F11: ACQUALAGNA | G11: =PROPER(F11) -> Acqualagna | H11: www.birraalpozzo.it | I11: =IF(ISERROR(FIND("@",H11)),"SITO","EMAIL") -> SITO | J11: =IF(I11="SITO",H11," ") -> www.birraalpozzo.it | K11: info@birraalpozzo.it | L11: =IF(ISERROR(FIND("@",K11)),"SITO","EMAIL") -> EMAIL | M11: =IF(L11="EMAIL",K11, " ") -> info@birraalpozzo.it | N11: =IF(J11<>" ", J11, "N/a") -> www.birraalpozzo.it | O11: =IF(M11 <> " ", M11,"N/a") -> info@birraalpozzo.it | Q11: RIFUGI | S11: BIRRA AL POZZO
A12: BED & BREAKFAST | B12: B&B CRISTINI CRISTINA | C12: strada frontino 23 | D12: =PROPER(C12) -> Strada Frontino 23 | E12: ACQUALAGNA | F12: ACQUALAGNA | G12: =PROPER(F12) -> Acqualagna | H12: N/a | I12: =IF(ISERROR(FIND("@",H12)),"SITO","EMAIL") -> SITO | J12: =IF(I12="SITO",H12," ") -> N/a | K12: cri.cristini@alice.it | L12: =IF(ISERROR(FIND("@",K12)),"SITO","EMAIL") -> EMAIL | M12: =IF(L12="EMAIL",K12, " ") -> cri.cristini@alice.it | N12: =IF(J12<>" ", J12, "N/a") -> N/a | O12: =IF(M12 <> " ", M12,"N/a") -> cri.cristini@alice.it | Q12: RESIDENZE TURISTICO ALBERGHIERE | S12: B&B CRISTINI CRISTINA
A13: BED & BREAKFAST | B13: B&B MARTELLONI CESARE | C13: via pianacce 67 | D13: =PROPER(C13) -> Via Pianacce 67 | E13: ACQUALAGNA | F13: ACQUALAGNA | G13: =PROPER(F13) -> Acqualagna | H13: www.lalocandadellabbazia.it | I13: =IF(ISERROR(FIND("@",H13)),"SITO","EMAIL") -> SITO | J13: =IF(I13="SITO",H13," ") -> www.lalocandadellabbazia.it | K13: info@lalocandadellabbazia.it | L13: =IF(ISERROR(FIND("@",K13)),"SITO","EMAIL") -> EMAIL | M13: =IF(L13="EMAIL",K13, " ") -> info@lalocandadellabbazia.it | N13: =IF(J13<>" ", J13, "N/a") -> www.lalocandadellabbazia.it | O13: =IF(M13 <> " ", M13,"N/a") -> info@lalocandadellabbazia.it | Q13: CAMPEGGI | S13: B&B MARTELLONI CESARE
A14: ALBERGHI | B14: ALBERGO MEUBLE' SHINE | C14: via aldo gamba 54 | D14: =PROPER(C14) -> Via Aldo Gamba 54 | E14: ACQUALAGNA | F14: ACQUALAGNA | G14: =PROPER(F14) -> Acqualagna | H14: N/a | I14: =IF(ISERROR(FIND("@",H14)),"SITO","EMAIL") -> SITO | J14: =IF(I14="SITO",H14," ") -> N/a | K14: N/a | L14: =IF(ISERROR(FIND("@",K14)),"SITO","EMAIL") -> SITO | M14: =IF(L14="EMAIL",K14, " ") | N14: =IF(J14<>" ", J14, "N/a") -> N/a | O14: =IF(M14 <> " ", M14,"N/a") -> N/a | Q14: STABILIMENTI BALNEARI | S14: ALBERGO MEUBLE' SHINE
... A16: ALBERGHI | B16: ALBERGO ANTICO FURLO | C16: via Flaminia 66 | D16: =PROPER(C16) -> Via Flaminia 66 | E16: ACQUALAGNA | F16: ACQUALAGNA | G16: =PROPER(F16) -> Acqualagna | H16: www.anticofurlo.it | I16: =IF(ISERROR(FIND("@",H16)),"SITO","EMAIL") -> SITO | J16: =IF(I16="SITO",H16," ") -> www.anticofurlo.it | K16: info@anticofurlo.it | L16: =IF(ISERROR(FIND("@",K16)),"SITO","EMAIL") -> EMAIL | M16: =IF(L16="EMAIL",K16, " ") -> info@anticofurlo.it | N16: =IF(J16<>" ", J16, "N/a") -> www.anticofurlo.it | O16: =IF(M16 <> " ", M16,"N/a") -> info@anticofurlo.it | Q16: VILLAGGI TURISTICI | S16: ALBERGO ANTICO FURLO
A17: TURISMO RURALE | B17: CA' GARAVANO | C17: strada Frontino 21 | D17: =PROPER(C17) -> Strada Frontino 21 | E17: ACQUALAGNA | F17: ACQUALAGNA | G17: =PROPER(F17) -> Acqualagna | H17: www.cagaravano.com | I17: =IF(ISERROR(FIND("@",H17)),"SITO","EMAIL") -> SITO | J17: =IF(I17="SITO",H17," ") -> www.cagaravano.com | K17: urbini.alessandro@alice.it | L17: =IF(ISERROR(FIND("@",K17)),"SITO","EMAIL") -> EMAIL | M17: =IF(L17="EMAIL",K17, " ") -> urbini.alessandro@alice.it | N17: =IF(J17<>" ", J17, "N/a") -> www.cagaravano.com | O17: =IF(M17 <> " ", M17,"N/a") -> urbini.alessandro@alice.it | S17: CA' GARAVANO
A18: ALTRI ALLOGGI PRIVATI | B18: IL CONIO DI DI GIOVANNI FEDERICO | C18: strada pietralatra 1 | D18: =PROPER(C18) -> Strada Pietralatra 1 | E18: ACQUALAGNA | F18: ACQUALAGNA | G18: =PROPER(F18) -> Acqualagna | H18: N/a | I18: =IF(ISERROR(FIND("@",H18)),"SITO","EMAIL") -> SITO | J18: =IF(I18="SITO",H18," ") -> N/a | K18: N/a | L18: =IF(ISERROR(FIND("@",K18)),"SITO","EMAIL") -> SITO | M18: =IF(L18="EMAIL",K18, " ") | N18: =IF(J18<>" ", J18, "N/a") -> N/a | O18: =IF(M18 <> " ", M18,"N/a") -> N/a | S18: IL CONIO DI DI GIOVANNI FEDERICO
A19: ALLOGGI AGRITURISTICI | B19: AGRITURISMO I CONTI | C19: via Pieve del Colle 11 b | D19: =PROPER(C19) -> Via Pieve Del Colle 11 B | E19: ACQUALAGNA | F19: pieve del colle | G19: =PROPER(F19) -> Pieve Del Colle | H19: www.agriturismoiconti.it | I19: =IF(ISERROR(FIND("@",H19)),"SITO","EMAIL") -> SITO | J19: =IF(I19="SITO",H19," ") -> www.agriturismoiconti.it | K19: info@agriturismoiconti.it | L19: =IF(ISERROR(FIND("@",K19)),"SITO","EMAIL") -> EMAIL | M19: =IF(L19="EMAIL",K19, " ") -> info@agriturismoiconti.it | N19: =IF(J19<>" ", J19, "N/a") -> www.agriturismoiconti.it | O19: =IF(M19 <> " ", M19,"N/a") -> info@agriturismoiconti.it | S19: AGRITURISMO I CONTI
A20: ALLOGGI AGRITURISTICI | B20: LA COLOMBARA | C20: strada Frontino 24 | D20: =PROPER(C20) -> Strada Frontino 24 | E20: ACQUALAGNA | F20: N/a | G20: =PROPER(F20) -> N/A | H20: N/a | I20: =IF(ISERROR(FIND("@",H20)),"SITO","EMAIL") -> SITO | J20: =IF(I20="SITO",H20," ") -> N/a | K20: N/a | L20: =IF(ISERROR(FIND("@",K20)),"SITO","EMAIL") -> SITO | M20: =IF(L20="EMAIL",K20, " ") | N20: =IF(J20<>" ", J20, "N/a") -> N/a | O20: =IF(M20 <> " ", M20,"N/a") -> N/a | S20: LA COLOMBARA
A21: ALTRI ALLOGGI PRIVATI | B21: STROPPA GIUSEPPE | C21: strada San Gregorio 12 | D21: =PROPER(C21) -> Strada San Gregorio 12 | E21: ACQUALAGNA | F21: Acqualagna | G21: =PROPER(F21) -> Acqualagna | H21: http://lapanoramicadastroppa.webstarts.com/ | I21: =IF(ISERROR(FIND("@",H21)),"SITO","EMAIL") -> SITO | J21: =IF(I21="SITO",H21," ") -> http://lapanoramicadastroppa.webstarts.com/ | K21: stroppag@libero.it | L21: =IF(ISERROR(FIND("@",K21)),"SITO","EMAIL") -> EMAIL | M21: =IF(L21="EMAIL",K21, " ") -> stroppag@libero.it | N21: =IF(J21<>" ", J21, "N/a") -> http://lapanoramicadastroppa.webstarts.com/ | O21: =IF(M21 <> " ", M21,"N/a") -> stroppag@libero.it | S21: STROPPA GIUSEPPE
A22: ALTRI ALLOGGI PRIVATI | B22: SERAFINI GIORGIA | C22: N/a | D22: =PROPER(C22) -> N/A | E22: ACQUALAGNA | F22: N/a | G22: =PROPER(F22) -> N/A | H22: N/a | I22: =IF(ISERROR(FIND("@",H22)),"SITO","EMAIL") -> SITO | J22: =IF(I22="SITO",H22," ") -> N/a | K22: N/a | L22: =IF(ISERROR(FIND("@",K22)),"SITO","EMAIL") -> SITO | M22: =IF(L22="EMAIL",K22, " ") | N22: =IF(J22<>" ", J22, "N/a") -> N/a | O22: =IF(M22 <> " ", M22,"N/a") -> N/a | S22: SERAFINI GIORGIA
A23: ALTRI ALLOGGI PRIVATI | B23: BETTI VINCENZO | C23: via Pole 69 | D23: =PROPER(C23) -> Via Pole 69 | E23: ACQUALAGNA | F23: N/a | G23: =PROPER(F23) -> N/A | H23: N/a | I23: =IF(ISERROR(FIND("@",H23)),"SITO","EMAIL") -> SITO | J23: =IF(I23="SITO",H23," ") -> N/a | K23: N/a | L23: =IF(ISERROR(FIND("@",K23)),"SITO","EMAIL") -> SITO | M23: =IF(L23="EMAIL",K23, " ") | N23: =IF(J23<>" ", J23, "N/a") -> N/a | O23: =IF(M23 <> " ", M23,"N/a") -> N/a | S23: BETTI VINCENZO
A24: ALLOGGI IN AFFITTO | B24: MARCHEHOLIDAY - CASALE DEGLI ULIVI | C24: strada San Gregorio 1 | D24: =PROPER(C24) -> Strada San Gregorio 1 | E24: ACQUALAGNA | F24: loc.Ca Donnino | G24: =PROPER(F24) -> Loc.Ca Donnino | H24: www.marcheholiday.it/ulivi | I24: =IF(ISERROR(FIND("@",H24)),"SITO","EMAIL") -> SITO | J24: =IF(I24="SITO",H24," ") -> www.marcheholiday.it/ulivi | K24: info@marcheholiday.it | L24: =IF(ISERROR(FIND("@",K24)),"SITO","EMAIL") -> EMAIL | M24: =IF(L24="EMAIL",K24, " ") -> info@marcheholiday.it | N24: =IF(J24<>" ", J24, "N/a") -> www.marcheholiday.it/ulivi | O24: =IF(M24 <> " ", M24,"N/a") -> info@marcheholiday.it | S24: MARCHEHOLIDAY - CASALE DEGLI ULIVI
A25: AREE DI SOSTA (PLEIN AIR) | B25: AREA SOSTA CAMPER PARCO LE QUERCE | C25: via Pianacce 1 | D25: =PROPER(C25) -> Via Pianacce 1 | E25: ACQUALAGNA | F25: RISERVA NATURALE STATALE GOLA DEL FURLO | G25: =PROPER(F25) -> Riserva Naturale Statale Gola Del Furlo | H25: parcodelfurlo.it | I25: =IF(ISERROR(FIND("@",H25)),"SITO","EMAIL") -> SITO | J25: =IF(I25="SITO",H25," ") -> parcodelfurlo.it | K25: info@parcodelfurlo.it | L25: =IF(ISERROR(FIND("@",K25)),"SITO","EMAIL") -> EMAIL | M25: =IF(L25="EMAIL",K25, " ") -> info@parcodelfurlo.it | N25: =IF(J25<>" ", J25, "N/a") -> parcodelfurlo.it | O25: =IF(M25 <> " ", M25,"N/a") -> info@parcodelfurlo.it | S25: AREA SOSTA CAMPER PARCO LE QUERCE
A26: ALTRI ALLOGGI PRIVATI | B26: BACCHIOCCHI MARIA ELISA | C26: via San Gregorio 17 | D26: =PROPER(C26) -> Via San Gregorio 17 | E26: ACQUALAGNA | F26: N/a | G26: =PROPER(F26) -> N/A | H26: N/a | I26: =IF(ISERROR(FIND("@",H26)),"SITO","EMAIL") -> SITO | J26: =IF(I26="SITO",H26," ") -> N/a | K26: remigio.battistelli@gmail.com | L26: =IF(ISERROR(FIND("@",K26)),"SITO","EMAIL") -> EMAIL | M26: =IF(L26="EMAIL",K26, " ") -> remigio.battistelli@gmail.com | N26: =IF(J26<>" ", J26, "N/a") -> N/a | O26: =IF(M26 <> " ", M26,"N/a") -> remigio.battistelli@gmail.com | S26: BACCHIOCCHI MARIA ELISA
A27: ALTRI ALLOGGI PRIVATI | B27: MARCHETTI LORENZA | C27: via Fossato 37/b | D27: =PROPER(C27) -> Via Fossato 37/B | E27: ACQUALAGNA | F27: N/a | G27: =PROPER(F27) -> N/A | H27: N/a | I27: =IF(ISERROR(FIND("@",H27)),"SITO","EMAIL") -> SITO | J27: =IF(I27="SITO",H27," ") -> N/a | K27: thomas.clementi@hotmail.it | L27: =IF(ISERROR(FIND("@",K27)),"SITO","EMAIL") -> EMAIL | M27: =IF(L27="EMAIL",K27, " ") -> thomas.clementi@hotmail.it | N27: =IF(J27<>" ", J27, "N/a") -> N/a | O27: =IF(M27 <> " ", M27,"N/a") -> thomas.clementi@hotmail.it | S27: MARCHETTI LORENZA
A28: BED & BREAKFAST | B28: B&B BISCUBIO | C28: via Circonvallazione 46 | D28: =PROPER(C28) -> Via Circonvallazione 46 | E28: APECCHIO | F28: N/a | G28: =PROPER(F28) -> N/A | H28: N/a | I28: =IF(ISERROR(FIND("@",H28)),"SITO","EMAIL") -> SITO | J28: =IF(I28="SITO",H28," ") -> N/a | K28: marcellamartinelli17@gmail.com | L28: =IF(ISERROR(FIND("@",K28)),"SITO","EMAIL") -> EMAIL | M28: =IF(L28="EMAIL",K28, " ") -> marcellamartinelli17@gmail.com | N28: =IF(J28<>" ", J28, "N/a") -> N/a | O28: =IF(M28 <> " ", M28,"N/a") -> marcellamartinelli17@gmail.com | S28: B&B BISCUBIO
... A6106: BED & BREAKFAST | B6106: B&B LA PINETINA | C6106: via IV Novembre 8 | D6106: =PROPER(C6106) -> Via Iv Novembre 8 | E6106: PORTO SAN GIORGIO | F6106: N/a | G6106: =PROPER(F6106) -> N/A | H6106: N/a | I6106: =IF(ISERROR(FIND("@",H6106)),"SITO","EMAIL") -> SITO | J6106: =IF(I6106="SITO",H6106," ") -> N/a | K6106: info@bb-lapinetina.it | L6106: =IF(ISERROR(FIND("@",K6106)),"SITO","EMAIL") -> EMAIL | M6106: =IF(L6106="EMAIL",K6106, " ") -> info@bb-lapinetina.it | N6106: =IF(J6106<>" ", J6106, "N/a") -> N/a | O6106: =IF(M6106 <> " ", M6106,"N/a") -> info@bb-lapinetina.it | S6106: B&B LA PINETINA
A6107: BED & BREAKFAST | B6107: B&B da NONNA SOLE | C6107: strada statale Nord 210 39 | D6107: =PROPER(C6107) -> Strada Statale Nord 210 39 | E6107: PORTO SAN GIORGIO | F6107: . | G6107: =PROPER(F6107) -> . | H6107: . | I6107: =IF(ISERROR(FIND("@",H6107)),"SITO","EMAIL") -> SITO | J6107: N/a | K6107: tania.ferroni@tiscali.it | L6107: =IF(ISERROR(FIND("@",K6107)),"SITO","EMAIL") -> EMAIL | M6107: =IF(L6107="EMAIL",K6107, " ") -> tania.ferroni@tiscali.it | N6107: =IF(J6107<>" ", J6107, "N/a") -> N/a | O6107: =IF(M6107 <> " ", M6107,"N/a") -> tania.ferroni@tiscali.it | S6107: B&B da NONNA SOLE
A6108: BED & BREAKFAST | B6108: B&B INTERNO 24 | C6108: via Rossini 20 | D6108: =PROPER(C6108) -> Via Rossini 20 | E6108: PORTO SAN GIORGIO | F6108: Porto San Giorgio | G6108: =PROPER(F6108) -> Porto San Giorgio | H6108: N/a | I6108: =IF(ISERROR(FIND("@",H6108)),"SITO","EMAIL") -> SITO | J6108: =IF(I6108="SITO",H6108," ") -> N/a | K6108: achristina@libero.it | L6108: =IF(ISERROR(FIND("@",K6108)),"SITO","EMAIL") -> EMAIL | M6108: =IF(L6108="EMAIL",K6108, " ") -> achristina@libero.it | N6108: =IF(J6108<>" ", J6108, "N/a") -> N/a | O6108: =IF(M6108 <> " ", M6108,"N/a") -> achristina@libero.it | S6108: B&B INTERNO 24
A6109: STABILIMENTI BALNEARI | B6109: CHALET 14 B | C6109: N/a | D6109: =PROPER(C6109) -> N/A | E6109: PORTO SAN GIORGIO | F6109: N/a | G6109: =PROPER(F6109) -> N/A | H6109: paolettapolidori@libero.it | I6109: =IF(ISERROR(FIND("@",H6109)),"SITO","EMAIL") -> EMAIL | J6109: =IF(I6109="SITO",H6109," ") | K6109: N/a | L6109: =IF(ISERROR(FIND("@",K6109)),"SITO","EMAIL") -> SITO | M6109: =IF(L6109="EMAIL",K6109, " ") | N6109: =IF(J6109<>" ", J6109, "N/a") -> N/a | O6109: =IF(M6109 <> " ", M6109,"N/a") -> N/a | S6109: CHALET 14 B
A6110: BED & BREAKFAST | B6110: B&B BELSIT | C6110: via Tiziano Vecellio 49 | D6110: =PROPER(C6110) -> Via Tiziano Vecellio 49 | E6110: PORTO SAN GIORGIO | F6110: N/a | G6110: =PROPER(F6110) -> N/A | H6110: www.bedandbreakfastbelsit.it | I6110: =IF(ISERROR(FIND("@",H6110)),"SITO","EMAIL") -> SITO | J6110: =IF(I6110="SITO",H6110," ") -> www.bedandbreakfastbelsit.it | K6110: info@bedandbreakfastbelsit.it | L6110: =IF(ISERROR(FIND("@",K6110)),"SITO","EMAIL") -> EMAIL | M6110: =IF(L6110="EMAIL",K6110, " ") -> info@bedandbreakfastbelsit.it | N6110: =IF(J6110<>" ", J6110, "N/a") -> www.bedandbreakfastbelsit.it | O6110: =IF(M6110 <> " ", M6110,"N/a") -> info@bedandbreakfastbelsit.it | S6110: B&B BELSIT
A6111: BED & BREAKFAST | B6111: B&B AL MARE di STEFANIA D'ANGELO | C6111: lungomare Gramsci 449 | D6111: =PROPER(C6111) -> Lungomare Gramsci 449 | E6111: PORTO SAN GIORGIO | F6111: N/a | G6111: =PROPER(F6111) -> N/A | H6111: www.bb-almare.it | I6111: =IF(ISERROR(FIND("@",H6111)),"SITO","EMAIL") -> SITO | J6111: =IF(I6111="SITO",H6111," ") -> www.bb-almare.it | K6111: info@bb-almare.it | L6111: =IF(ISERROR(FIND("@",K6111)),"SITO","EMAIL") -> EMAIL | M6111: =IF(L6111="EMAIL",K6111, " ") -> info@bb-almare.it | N6111: =IF(J6111<>" ", J6111, "N/a") -> www.bb-almare.it | O6111: =IF(M6111 <> " ", M6111,"N/a") -> info@bb-almare.it | S6111: B&B AL MARE di STEFANIA D'ANGELO
A6112: AREE DI SOSTA (PLEIN AIR) | B6112: AREA SOSTA CAMPER LA PERLA DELL'ADRIATICO | C6112: via San Martino 13 | D6112: =PROPER(C6112) -> Via San Martino 13 | E6112: PORTO SAN GIORGIO | F6112: porto san giorgio | G6112: =PROPER(F6112) -> Porto San Giorgio | H6112: www.areaperladelladriatico.it | I6112: =IF(ISERROR(FIND("@",H6112)),"SITO","EMAIL") -> SITO | J6112: =IF(I6112="SITO",H6112," ") -> www.areaperladelladriatico.it | K6112: info@areaperladelladriatico.it | L6112: =IF(ISERROR(FIND("@",K6112)),"SITO","EMAIL") -> EMAIL | M6112: =IF(L6112="EMAIL",K6112, " ") -> info@areaperladelladriatico.it | N6112: =IF(J6112<>" ", J6112, "N/a") -> www.areaperladelladriatico.it | O6112: =IF(M6112 <> " ", M6112,"N/a") -> info@areaperladelladriatico.it | S6112: AREA SOSTA CAMPER LA PERLA DELL'ADRIATICO
A6113: ALLOGGI IN AFFITTO | B6113: AFFITTACAMERE SAN GIORGIO | C6113: via XX Settembre 196 | D6113: =PROPER(C6113) -> Via Xx Settembre 196 | E6113: PORTO SAN GIORGIO | F6113: PORTO SAN GIORGIO | G6113: =PROPER(F6113) -> Porto San Giorgio | H6113: N/a | I6113: =IF(ISERROR(FIND("@",H6113)),"SITO","EMAIL") -> SITO | J6113: =IF(I6113="SITO",H6113," ") -> N/a | K6113: pensione.san.giorgio@hotmail.it | L6113: =IF(ISERROR(FIND("@",K6113)),"SITO","EMAIL") -> EMAIL | M6113: =IF(L6113="EMAIL",K6113, " ") -> pensione.san.giorgio@hotmail.it | N6113: =IF(J6113<>" ", J6113, "N/a") -> N/a | O6113: =IF(M6113 <> " ", M6113,"N/a") -> pensione.san.giorgio@hotmail.it | S6113: AFFITTACAMERE SAN GIORGIO
A6114: BED & BREAKFAST | B6114: B&B GREEN HARMONY di BIANCA MARIA CASALI | C6114: contrada Misericordia 6 | D6114: =PROPER(C6114) -> Contrada Misericordia 6 | E6114: PORTO SAN GIORGIO | F6114: N/a | G6114: =PROPER(F6114) -> N/A | H6114: N/a | I6114: =IF(ISERROR(FIND("@",H6114)),"SITO","EMAIL") -> SITO | J6114: =IF(I6114="SITO",H6114," ") -> N/a | K6114: bianca.casali@virgilio.it | L6114: =IF(ISERROR(FIND("@",K6114)),"SITO","EMAIL") -> EMAIL | M6114: =IF(L6114="EMAIL",K6114, " ") -> bianca.casali@virgilio.it | N6114: =IF(J6114<>" ", J6114, "N/a") -> N/a | O6114: =IF(M6114 <> " ", M6114,"N/a") -> bianca.casali@virgilio.it | S6114: B&B GREEN HARMONY di BIANCA MARIA CASALI
A6115: BED & BREAKFAST | B6115: VILLA MONTANARI ROSATI | C6115: VIA A.COSTA 15 | D6115: =PROPER(C6115) -> Via A.Costa 15 | E6115: PORTO SAN GIORGIO | F6115: PORTO SAN GIORGIO | G6115: =PROPER(F6115) -> Porto San Giorgio | H6115: N/a | I6115: =IF(ISERROR(FIND("@",H6115)),"SITO","EMAIL") -> SITO | J6115: =IF(I6115="SITO",H6115," ") -> N/a | K6115: villamontanarirosati@gmail.com | L6115: =IF(ISERROR(FIND("@",K6115)),"SITO","EMAIL") -> EMAIL | M6115: =IF(L6115="EMAIL",K6115, " ") -> villamontanarirosati@gmail.com | N6115: =IF(J6115<>" ", J6115, "N/a") -> N/a | O6115: =IF(M6115 <> " ", M6115,"N/a") -> villamontanarirosati@gmail.com | S6115: VILLA MONTANARI ROSATI
A6116: BED & BREAKFAST | B6116: B&B TRENTHOUSE | C6116: VIA TORQUATO TASSO 3 | D6116: =PROPER(C6116) -> Via Torquato Tasso 3 | E6116: PORTO SAN GIORGIO | F6116: PORTO SAN GIORGIO | G6116: =PROPER(F6116) -> Porto San Giorgio | H6116: N/a | I6116: =IF(ISERROR(FIND("@",H6116)),"SITO","EMAIL") -> SITO | J6116: =IF(I6116="SITO",H6116," ") -> N/a | K6116: loryt59@gmail.com | L6116: =IF(ISERROR(FIND("@",K6116)),"SITO","EMAIL") -> EMAIL | M6116: =IF(L6116="EMAIL",K6116, " ") -> loryt59@gmail.com | N6116: =IF(J6116<>" ", J6116, "N/a") -> N/a | O6116: =IF(M6116 <> " ", M6116,"N/a") -> loryt59@gmail.com | S6116: B&B TRENTHOUSE
A6117: BED & BREAKFAST | B6117: B&B A CASA DI ADRIA | C6117: via Lepanto 12 | D6117: =PROPER(C6117) -> Via Lepanto 12 | E6117: PORTO SAN GIORGIO | F6117: N/a | G6117: =PROPER(F6117) -> N/A | H6117: www.bebadria.it | I6117: =IF(ISERROR(FIND("@",H6117)),"SITO","EMAIL") -> SITO | J6117: =IF(I6117="SITO",H6117," ") -> www.bebadria.it | K6117: info@bebadria.it | L6117: =IF(ISERROR(FIND("@",K6117)),"SITO","EMAIL") -> EMAIL | M6117: =IF(L6117="EMAIL",K6117, " ") -> info@bebadria.it | N6117: =IF(J6117<>" ", J6117, "N/a") -> www.bebadria.it | O6117: =IF(M6117 <> " ", M6117,"N/a") -> info@bebadria.it | S6117: B&B A CASA DI ADRIA
A6118: BED & BREAKFAST | B6118: B&B MARCHE TOURISM | C6118: Via Santa Vittoria 33 | D6118: =PROPER(C6118) -> Via Santa Vittoria 33 | E6118: PORTO SAN GIORGIO | F6118: PORTO SAN GIORGIO | G6118: =PROPER(F6118) -> Porto San Giorgio | H6118: www.marche-tourism.com | I6118: =IF(ISERROR(FIND("@",H6118)),"SITO","EMAIL") -> SITO | J6118: =IF(I6118="SITO",H6118," ") -> www.marche-tourism.com | K6118: prenotazioni@marche-tourism.com | L6118: =IF(ISERROR(FIND("@",K6118)),"SITO","EMAIL") -> EMAIL | M6118: =IF(L6118="EMAIL",K6118, " ") -> prenotazioni@marche-tourism.com | N6118: =IF(J6118<>" ", J6118, "N/a") -> www.marche-tourism.com | O6118: =IF(M6118 <> " ", M6118,"N/a") -> prenotazioni@marche-tourism.com | S6118: B&B MARCHE TOURISM
...

Sheet STRUTTURE
A1: Categoria | B1: Strutture | C1: Indirizzo | D1: Città | E1: Località | F1: Indirizzo internet | G1: Indirizzo di posta elettronica
A2: TURISMO RURALE | B2: COUNTRY HOUSE LOCALITA' GIROFALCO | C2: Via Girfalco, 26 | D2: URBINO | E2: N/A | F2: www.girfalco.it | G2: info@girfalco.it
A3: ALTRI ALLOGGI PRIVATI | B3: STAGNOZZI STEFANIA | C3: Via Candigliano 5 | D3: ACQUALAGNA | E3: Acqualagna | F3: N/a | G3: gigliovitto@libero.it
A4: ALTRI ALLOGGI PRIVATI | B4: GORGOLINI ALESSANDRO | C4: Via San Gregorio 9 | D4: ACQUALAGNA | E4: Acqualagna | F4: N/a | G4: ale.gorgolini@gmail.com
A5: ALBERGHI | B5: LEON D'ORO | C5: Via Flaminia 213 | D5: ACQUALAGNA | E5: Acqualagna | F5: N/a | G5: N/a
A6: ALBERGHI | B6: ALBERGO DOMUS MARIAE | C6: Viale Ezio Scaglioni 17 | D6: ACQUALAGNA | E6: Acqualagna | F6: N/a | G6: giulianaspini@gmail.com
A7: ALTRI ALLOGGI PRIVATI | B7: TORRE COLOMBARA DI FRONTINO | C7: Strada Frontino 24/B | D7: ACQUALAGNA | E7: Acqualagna | F7: N/a | G7: luccardi.sandro@gmail.com
A8: BED & BREAKFAST | B8: B&B AQUILEGIA | C8: Via Furlo 12 | D8: ACQUALAGNA | E8: Furlo | F8: www.aquilegiabeb.com | G8: info@aquilegiabeb.com
A9: ALLOGGI AGRITURISTICI | B9: DEL FRONTINO | C9: Strada Frontino 23 | D9: ACQUALAGNA | E9: Acqualagna | F9: N/a | G9: N/a
A10: ALBERGHI | B10: LA GINESTRA | C10: Via Furlo 17 | D10: ACQUALAGNA | E10: Acqualagna | F10: www.ginestrafurlo.it | G10: info@ginestrafurlo.it
A11: ALBERGHI | B11: BIRRA AL POZZO | C11: Via Pianacce 12 | D11: ACQUALAGNA | E11: Acqualagna | F11: www.birraalpozzo.it | G11: info@birraalpozzo.it
A12: BED & BREAKFAST | B12: B&B CRISTINI CRISTINA | C12: Strada Frontino 23 | D12: ACQUALAGNA | E12: Acqualagna | F12: N/a | G12: cri.cristini@alice.it
... A6259: ALLOGGI AGRITURISTICI | B6259: POMO D'ORO | C6259: Contrada San Pietro 6 | D6259: TORRE SAN PATRIZIO | E6259: N/A | F6259: www.agriturismopomodoro.com | G6259: info@agriturismopomodoro.com

Sheet RICERCA
B1: RICERCA STRUTTURA
B3: NOME STRUTTURA | C3: LA GINESTRA
B4: CITTA' | C4: =_xlfn.XLOOKUP($C$3,'Strutture ricettive'!B:B,'Strutture ricettive'!E:E) -> ACQUALAGNA
B5: LOCALITA' | C5: =_xlfn.XLOOKUP($C$3,'Strutture ricettive'!B:B,'Strutture ricettive'!G:G) -> Acqualagna
B6: INDIRIZZO | C6: =_xlfn.XLOOKUP($C$3,'Strutture ricettive'!B:B,'Strutture ricettive'!D:D) -> Via Furlo 17
B7: EMAIL | C7: =_xlfn.XLOOKUP($C$3,'Strutture ricettive'!B:B,'Strutture ricettive'!O:O) -> info@ginestrafurlo.it
B8: INDIRIZZO WEB | C8: =_xlfn.XLOOKUP($C$3,'Strutture ricettive'!B:B,'Strutture ricettive'!N:N) -> www.ginestrafurlo.it
B9: Numero totale strutture | C9: =COUNTA('Strutture ricettive'!$B$2:$B$6259) -> 6258
B10: Numero strutture per LOCALITA' | C10: =COUNTIF('Strutture ricettive'!$E$2:$E$6259,RICERCA!C4) -> 25

Sheet PIVOT
A1: Città | B1: (Tutto)
A3: Etichette di riga | B3: Conteggio di Strutture
A4: ALBERGHI | B4: 814
A5: ALLOGGI AGRITURISTICI | B5: 830
A6: ALLOGGI IN AFFITTO | B6: 541
A7: ALTRI ALLOGGI PRIVATI | B7: 721
A8: ALTRI ESERCIZI RICETTIVI | B8: 13
A9: AREE DI SOSTA (PLEIN AIR) | B9: 86
A10: BED & BREAKFAST | B10: 1809
A11: CAMPEGGI | B11: 93
A12: CASE PER FERIE | B12: 82
A13: OSTELLI PER LA GIOVENTU' | B13: 30
A14: RESIDENZE TURISTICO ALBERGHIERE | B14: 52
A15: RIFUGI | B15: 16
... A19: Totale complessivo | B19: 6258

Sheet Spiegazione 1
A1: ID | B1: PASSAGGIO | C1: SPIEGAZIONE | D1: COMMENTO
A2: 1 | B2: Filtrato intero intervallo nel foglio Strutture Ricettive | C2: ctrl+a > ordina e filtra > filtro
A3: =A2+1 -> 2 | B3: Sosituito spazi vuote nella colonna Località con N/a | C3: selezionato colonna località > ctrl+maiusc+s > sostituisci spazio vuoto con N/a > confronta intero contenuto della cella > sostituisci tutto
A4: =A3+1 -> 3 | B4: Nuova colonna Località con nomi con sola maiuscola iniziale | C4: inserisci colonna e poi formula =maiusc.iniziale
A5: =A4+1 -> 4 | B5: Nascosta vecchia colonna "Localita" | C5: Selezioni colonna > tasto destro > nascondi
A6: =A5+1 -> 5 | B6: Sistemato spazi vuoti con N/a e Solo maiuscolo in colonna Indirizzo e poi nascosta | C6: Stesso processo della colonna Località
A7: =A6+1 -> 6 | B7: Sosituito spazi vuote nelle colonna Sito Internet e Inidirrizo di posta elettronica con N/a | C7: selezionato le due colonne > ctrl+maiusc+s > sostituisci spazio vuoto con N/a > confronta intero contenuto della cella > sostituisci tutto
A8: =A7+1 -> 7 | B8: Sistemato colonne H e J, perhcè hanno alcuni dati invertiti. | C8: 1)Creato due colonne di appoggio accanto a ciascuna. Poi usata la formula =SE(VAL.ERRORE(TROVA("@";H2));"SITO";"EMAIL")* per avere nelle colonne di appoggia la dicitura EMAIL se nella colonna originale c'era l'@, altrimenti SITO; 2)Creato altre due conne dove ho inserito le formule =SE(testo="SITO"; valore originale) - per l'email rimaneva spazio vuoto dove non c'era email, quindi ho creato un altra colonna ancora e ho messo la seguente formula =SE(M2 <> " "; M2;"N/a") per avere appunto N/a negli spazi vuoti - fatto stesso discroso per internet, così abbiamo tolto tutti gli spazi vuoti; 3)Lasciato solo le due colonne finali e nascoste tutte le altre. PS. Nella colonna internet c'era un solo valore "." e l'ho sostituito manualmente con N/a". | D8: *Avevo provato la formula senza il val.errore, solo con il trova, ma non mi dava il risultato voluto, in quanto la funzione TROVA non trovando @ dava errore e non dava quindi un'alternativa. Ho cercato su internet e visto che per ottenere quello che volevo fare, doveva essere preceduta dalla formula val.errore, dove se nella cella non si trovava il @ e la formula con il trova restituiva errore, ottenevamo il VERO -> serviva quindi per garantire la condizione booleana attraverso la quale funziona la funzione =se(). PS. Alcune strutture avevano due email, anziché email e sito internet. Mi sono precouppato facendo questo passaggio che almeno ne rimanesse una email.
A9: =A8+1 -> 8 | B9: Creato nuova colonna elenco strutture e usato per creare menù a tendina con le singole strutture nel foglio RICERCA | C9: Creato nuova colonna "ELENCO STRUTTURE" e incollato valori colonna B da B2. Poi su foglio RICERCA selezionato celle C3 > Dati > Convalida Dati > selezionato Elenco > selezionato intervallo colonna "ELENCO STRUTTURA"
A10: =A9+1 -> 9 | B10: Calcolato numero totale strutture | C10: Con la seguente formula =CONTA.VALORI('Strutture ricettive'!$B$2:$B$6259)
A11: =A10+1 -> 10 | B11: Calcolato numero strutture per Città | C11: Con la seguente formula =CONTA.SE('Strutture ricettive'!$E$2:$E$6259;RICERCA!C4)
A12: =A11+1 -> 11 | B12: Aggiunto alla tabella la voce Località
A13: =A12+1 -> 12 | B13: Applicati i rispettivi cerca.X per trovare i valori richiesti dalla tabella in riferimento alla cella c3. | C13: Formule usate sono: =CERCA.X($C$3;'Strutture ricettive'!B:B;'Strutture ricettive'!E:E) per Città - =CERCA.X($C$3;'Strutture ricettive'!B:B;'Strutture ricettive'!G:G) per Località - =CERCA.X($C$3;'Strutture ricettive'!B:B;'Strutture ricettive'!D:D) per Indirizzo - =CERCA.X($C$3;'Strutture ricettive'!B:B;'Strutture ricettive'!O:O) per Email - =CERCA.X($C$3;'Strutture ricettive'!B:B;'Strutture ricettive'!N:N) per Indirizzo WEB

Sheet Spiegazione 2
A1: ID | B1: PASSAGGIO | C1: SPIEGAZIONE
A2: 1 | B2: Copiato le colonne che mi interessavano in un nuovo foglio 'STRUTTURE' | C2: Fatto questo perché nel foglio Strutture Ricettive c'erano colonne nascoste e non riuscivo a fare la Pivot.
A3: =A2+1 -> 2 | B3: Selezionato intero intervallo nel foglio Strutture Ricettive e creata tabella Pivot in nuovo foglio PIVOT | C3: ctrl+a sull'intervallo > inserisci > tabella pivot > da tabella intervallo > inserito in nuovo foglio lavoro 'PIVOT'
A4: =A3+1 -> 3 | B4: Aggiunto a righe: categoria, filtri: città e valori: strutture con come calcolo il Conteggio.
A5: =A4+1 -> 4 | B5: Aggiunto un Istogramma per avere un'idea generale sul tipo e numero di strutture in quella località.
